Workbook

Sheet Legend
A1: HDPE Drum & Accessories — Normalized SKU Data Model
A2: Context: Pyramid Technoplast Ltd (pyramidtechnoplast.com) — Plastic Barrels vertical
A4: Why normalized | B4: The earlier flat sheet repeated Group SKU Name, Category, Product Type, Business Vertical on every one of 448 rows. This version splits that into 3 linked tables so each fact is stored exactly once, edited in exactly one place, and stays consistent.
A6: Table | B6: Contents & Key
A7: T1_ProductType (36 rows) | B7: One row per product family (e.g. Narrow Mouth Drum, PP Cap). Primary Key: Product Type ID. Holds Category, Business Vertical, Industry Standard Term — each stored once instead of repeated per SKU.
A8: T2_GroupSKU (79 rows) | B8: One row per parent/listing-level product (e.g. NMD-210 = Narrow Mouth Drum, 210 LTR). Primary Key: Group SKU Code. Foreign Key: Product Type ID → T1_ProductType. Holds Capacity/Size and variant count.
A9: T3_SKU (448 rows) | B9: One row per sellable item (the actual variant — color/weight/etc.). Primary Key: SKU Code. Foreign Key: Group SKU Code → T2_GroupSKU. Holds only variant-specific data: Variant description, Original Item Name, UOM, HSN.
A10: View_Combined (lookup) | B10: Not a master table — a formula-driven flat view (INDEX/MATCH against T1/T2/T3) that reconstructs the old wide format for filtering/exporting. Edit the source tables, not this sheet; it recalculates automatically.
A12: Relationship (ERD) | B12: T1_ProductType (1) ──< T2_GroupSKU (many) ──< T3_SKU (many)
B13: i.e. one Product Type has many Group SKUs; one Group SKU has many child SKUs.
A15: How to use
A16: Add a new SKU | B16: Just add a row to T3_SKU with a new SKU Code and the correct Group SKU Code (FK). No need to re-type Product Type/Category anywhere.
A17: Add a new Group SKU | B17: Add a row to T2_GroupSKU with a new Group SKU Code and the correct Product Type ID (FK).
A18: Rename/recategorize a Product Type | B18: Edit it once in T1_ProductType — it updates everywhere via the View sheet automatically.
A20: Notes & Assumptions (carried over)
A21: 1. | B21: Source: HDPE_DRUM_AND_ACCESSORIES_ITEM_MASTER.xlsx, sheet " CHECKING 060626", 448 item rows.
A22: 2. | B22: All Group SKU / SKU codes and IDs are newly generated for this exercise — proposed, remappable to your own scheme.
A23: 3. | B23: Weight (KG) on drums/cans = wall-thickness/grade tier, treated as a variant attribute inside T3_SKU, not a separate Group SKU.
A24: 4. | B24: "FOT" split into FOT Drum (has litre capacity) vs. FOT Cap/Ring/Lock accessories, per earlier analysis.
A25: 5. | B25: Business Vertical = "Plastic Barrels" for all rows (per Pyramid's own site structure) — this item master doesn't cover their IBC Container or MS Barrel lines.

Sheet T1_ProductType
A1: Product Type ID | B1: Product Type | C1: Category | D1: Business Vertical | E1: Industry Standard Term
A2: PT01 | B2: Bung | C2: Accessory | D2: Plastic Barrels
A3: PT02 | B3: Cap Seal | C3: Accessory | D3: Plastic Barrels
A4: PT03 | B4: Cap Spanner | C4: Accessory | D4: Plastic Barrels
A5: PT04 | B5: Cliching Cover | C5: Accessory | D5: Plastic Barrels
A6: PT05 | B6: Corner Protector | C6: Accessory | D6: Plastic Barrels
A7: PT06 | B7: DG Cap | C7: Accessory | D7: Plastic Barrels
A8: PT07 | B8: Drip Pan | C8: Accessory | D8: Plastic Barrels
A9: PT08 | B9: Dummy Cap | C9: Accessory | D9: Plastic Barrels
A10: PT09 | B10: Elbow (IBC) | C10: Accessory | D10: Plastic Barrels
A11: PT10 | B11: FOT Cap | C11: Accessory | D11: Plastic Barrels
A12: PT11 | B12: FOT Lock | C12: Accessory | D12: Plastic Barrels
A13: PT12 | B13: FOT Plastic Ring | C13: Accessory | D13: Plastic Barrels
... A31: PT30 | B31: Vent Fitting | C31: Accessory | D31: Plastic Barrels
A32: PT31 | B32: Jerry Can | C32: Can | D32: Plastic Barrels | E32: Jerry Can / Carboy
A33: PT32 | B33: M/Z Can | C33: Can | D33: Plastic Barrels | E33: Mouth-Zip Can
A34: PT33 | B34: Rocket Can | C34: Can | D34: Plastic Barrels | E34: Rocket Can
A35: PT34 | B35: FOT (Full Open Top) Drum | C35: Drum | D35: Plastic Barrels | E35: Fully Open Top Drum
A36: PT35 | B36: Narrow Mouth Drum | C36: Drum | D36: Plastic Barrels | E36: Tight Head Drum
A37: PT36 | B37: Wide Mouth Drum | C37: Drum | D37: Plastic Barrels | E37: Open Head Drum

Sheet T2_GroupSKU
A1: Group SKU Code | B1: Group SKU Name | C1: Product Type ID (FK) | D1: Capacity/Size Value | E1: Unit | F1: No. of SKUs (Variants)
A2: BUNG | B2: Bung | C2: PT01 | F2: 9
A3: CAPSL | B3: Cap Seal | C3: PT02 | F3: 2
A4: CAPSL-PR | B4: Printed Cap Seal (Branded) | C4: PT24 | F4: 42
A5: CAPSPN | B5: Cap Spanner | C5: PT03 | F5: 1
A6: CLCV | B6: Cliching Cover | C6: PT04 | F6: 2
A7: CRNP | B7: Corner Protector | C7: PT05 | F7: 3
A8: DGCAP-6IN | B8: DG Cap - 6.0" | C8: PT06 | D8: 6 | E8: INCH | F8: 2
A9: DMYCAP | B9: Dummy Cap | C9: PT08 | F9: 2
A10: DRPN | B10: Drip Pan | C10: PT07 | F10: 1
A11: ELB | B11: Elbow (IBC) | C11: PT09 | F11: 1
A12: FOTCAP-10IN | B12: FOT Cap - 10.0" | C12: PT10 | D12: 10 | E12: INCH | F12: 2
A13: FOTCAP-14IN | B13: FOT Cap - 14.0" | C13: PT10 | D13: 14 | E13: INCH | F13: 3
A14: FOTCAP-21IN | B14: FOT Cap - 21.0" | C14: PT10 | D14: 21 | E14: INCH | F14: 1
A15: FOTD-210 | B15: FOT (Full Open Top) Drum - 210.0 LTR | C15: PT34 | D15: 210 | E15: LTR | F15: 16
A16: FOTD-220 | B16: FOT (Full Open Top) Drum - 220.0 LTR | C16: PT34 | D16: 220 | E16: LTR | F16: 6
A17: FOTD-235 | B17: FOT (Full Open Top) Drum - 235.0 LTR | C17: PT34 | D17: 235 | E17: LTR | F17: 12
A18: FOTD-240 | B18: FOT (Full Open Top) Drum - 240.0 LTR | C18: PT34 | D18: 240 | E18: LTR | F18: 4
A19: FOTD-30 | B19: FOT (Full Open Top) Drum - 30.0 LTR | C19: PT34 | D19: 30 | E19: LTR | F19: 2
A20: FOTD-35 | B20: FOT (Full Open Top) Drum - 35.0 LTR | C20: PT34 | D20: 35 | E20: LTR | F20: 3
A21: FOTD-50 | B21: FOT (Full Open Top) Drum - 50.0 LTR | C21: PT34 | D21: 50 | E21: LTR | F21: 19
A22: FOTD-60 | B22: FOT (Full Open Top) Drum - 60.0 LTR | C22: PT34 | D22: 60 | E22: LTR | F22: 16
A23: FOTLOCK | B23: FOT Lock | C23: PT11 | F23: 1
A24: FOTPLRING | B24: FOT Plastic Ring | C24: PT12 | D24: 10 | E24: INCH | F24: 1
A25: FOTRBRING | B25: FOT Rubber Ring | C25: PT13 | D25: 10 | E25: INCH | F25: 2
A26: HDL | B26: Handle | C26: PT14 | F26: 6
A27: INS | B27: Insert | C27: PT15 | F27: 1
A28: INS-10IN | B28: Insert - 10.0" | C28: PT15 | D28: 10 | E28: INCH | F28: 1
A29: INS-1IN | B29: Insert - 1.0" | C29: PT15 | D29: 1 | E29: INCH | F29: 1
A30: INS-2IN | B30: Insert - 2.0" | C30: PT15 | D30: 2 | E30: INCH | F30: 2
A31: INS-6IN | B31: Insert - 6.0" | C31: PT15 | D31: 6 | E31: INCH | F31: 1
A32: INS-8IN | B32: Insert - 8.0" | C32: PT15 | D32: 8 | E32: INCH | F32: 1
A33: JC-25 | B33: Jerry Can - 25.0 LTR | C33: PT31 | D33: 25 | E33: LTR | F33: 1
A34: JC-30 | B34: Jerry Can - 30.0 LTR | C34: PT31 | D34: 30 | E34: LTR | F34: 5
A35: JC-35 | B35: Jerry Can - 35.0 LTR | C35: PT31 | D35: 35 | E35: LTR | F35: 18
A36: JC-40 | B36: Jerry Can - 40.0 LTR | C36: PT31 | D36: 40 | E36: LTR | F36: 4
A37: LUG | B37: Lugs | C37: PT16 | F37: 5
A38: MISC | B38: Other Accessory | C38: PT19 | F38: 1
A39: MSRING-10IN | B39: MS Ring - 10.0" | C39: PT18 | D39: 10 | E39: INCH | F39: 2
A40: MSRING-14IN | B40: MS Ring - 14.0" | C40: PT18 | D40: 14 | E40: INCH | F40: 3
...

Sheet T3_SKU
A1: SKU Code | B1: Group SKU Code (FK) | C1: Variant | D1: Original Item Name | E1: UOM | F1: HSN Code
A2: BUNG-ORG | B2: BUNG | C2: Orange | D2: BUNGS RING ORANGE | E2: NOS
A3: BUNG-V359 | B3: BUNG | C3: BUNGS RING | D3: BUNGS RING | E3: NOS | F3: 39235010
A4: BUNG-V408 | B4: BUNG | C4: BUNGS | D4: BUNGS | E4: nos | F4: 39235010
A5: BUNG-V409 | B5: BUNG | C5: 70mm / Ibc | D5: BUNGS 70 MM ( IBC ) | E5: NOS | F5: 39235010
A6: BUNG-V41 | B6: BUNG | C6: BUNGS DG | D6: BUNGS DG | E6: NOS | F6: 39235010
A7: BUNG-V442 | B7: BUNG | C7: 50mm / Ibc | D7: BUNGS 50 MM ( IBC ) | E7: NOS | F7: 39235010
A8: BUNG-V444 | B8: BUNG | C8: 50mm / Galaxy | D8: BUNGS 50 MM (GALAXY)
A9: BUNG-V445 | B9: BUNG | C9: BUNGS SOFT RING | D9: BUNGS SOFT RING
A10: BUNG-V447 | B10: BUNG | C10: 65mm | D10: TOP SEAL BUNGS 65 MM
A11: CAPSL-PR-BLK | B11: CAPSL-PR | C11: 50mm / Black / Black Rose | D11: MS CAP SEAL PRINTED 50 MM (BLACK ROSE) | E11: NOS | F11: 83099030
A12: CAPSL-PR-V22 | B12: CAPSL-PR | C12: 50mm / Aditya Birla Logo | D12: MS CAP SEAL PRINTED 50 MM (ADITYA BIRLA LOGO) | E12: NOS | F12: 83099090
A13: CAPSL-PR-V23 | B13: CAPSL-PR | C13: 75mm / Charbhuja Logo | D13: MS CAP SEAL PRINTED 75 MM (CHARBHUJA LOGO) | E13: NOS | F13: 83099030
A14: CAPSL-PR-V24 | B14: CAPSL-PR | C14: 50mm / Sika Logo | D14: MS CAP SEAL PRINTED 50 MM (SIKA LOGO) | E14: NOS | F14: 83099030
A15: CAPSL-PR-V25 | B15: CAPSL-PR | C15: 75mm / Bitchem Logo | D15: MS CAP SEAL PRINTED 75 MM (BITCHEM LOGO) | E15: NOS | F15: 83099030
A16: CAPSL-PR-V26 | B16: CAPSL-PR | C16: 75mm / Unitop Logo | D16: MS CAP SEAL PRINTED 75 MM (UNITOP LOGO) | E16: NOS
A17: CAPSL-PR-V27 | B17: CAPSL-PR | C17: 50mm / Chiripal Logo | D17: MS CAP SEAL PRINTED 50 MM (CHIRIPAL LOGO) | E17: NOS | F17: 83099030
A18: CAPSL-PR-V28 | B18: CAPSL-PR | C18: 50mm / Tashoil Logo | D18: MS CAP SEAL PRINTED 50 MM (TASHOIL LOGO ) | E18: nos | F18: 83099030
A19: CAPSL-PR-V29 | B19: CAPSL-PR | C19: 50mm / Aethel Logo | D19: MS CAP SEAL PRINTED 50 MM (AETHEL LOGO) | E19: NOS | F19: 83099090
A20: CAPSL-PR-V30 | B20: CAPSL-PR | C20: 50mm / Ansika Logo | D20: MS CAP SEAL PRINTED 50 MM (ANSIKA LOGO) | E20: NOS | F20: 83099030
A21: CAPSL-PR-V32 | B21: CAPSL-PR | C21: 50mm / Gfl Logo | D21: MS CAP SEAL PRINTED 50 MM (GFL LOGO) | E21: NOS | F21: 83099090
A22: CAPSL-PR-V33 | B22: CAPSL-PR | C22: 50mm / Gp Logo | D22: MS CAP SEAL PRINTED 50 MM (GP LOGO) | E22: NOS | F22: 83099030
A23: CAPSL-PR-V34 | B23: CAPSL-PR | C23: 50mm / Iol Logo | D23: MS CAP SEAL PRINTED 50 MM (IOL LOGO ) | E23: NOS | F23: 83099030
A24: CAPSL-PR-V35 | B24: CAPSL-PR | C24: 50mm / Maxwell Logo | D24: MS CAP SEAL PRINTED 50 MM (MAXWELL LOGO) | E24: NOS | F24: 83099030
A25: CAPSL-PR-V36 | B25: CAPSL-PR | C25: 50mm / Megamani Fine | D25: MS CAP SEAL PRINTED 50 MM (MEGAMANI FINE) | E25: NOS
A26: CAPSL-PR-V37 | B26: CAPSL-PR | C26: 50mm / Mfl Logo | D26: MS CAP SEAL PRINTED 50 MM (MFL LOGO) | E26: NOS | F26: 83099030
A27: CAPSL-PR-V38 | B27: CAPSL-PR | C27: 50mm / Solenis Logo | D27: MS CAP SEAL PRINTED 50 MM (SOLENIS LOGO) | E27: NOS | F27: 83099030
A28: CAPSL-PR-V39 | B28: CAPSL-PR | C28: 50mm / Bios Logo | D28: MS CAP SEAL PRINTED 50 MM (BIOS LOGO) | E28: nos | F28: 39235010
A29: CAPSL-PR-V40 | B29: CAPSL-PR | C29: 50mm / Bios Crop Logo | D29: MS CAP SEAL PRINTED 50 MM (BIOS CROP LOGO) | E29: NOS
A30: CAPSL-PR-V49 | B30: CAPSL-PR | C30: 50mm / Galata Chemicals | D30: MS CAP SEAL PRINTED 50 MM (GALATA CHEMICALS) | E30: NOS | F30: 83099090
A31: CAPSL-PR-V50 | B31: CAPSL-PR | C31: 50mm / Seal For Protection Logo | D31: MS CAP SEAL PRINTED 50 MM (SEAL FOR PROTECTION LOGO) | E31: NOS | F31: 83099030
A32: CAPSL-PR-V51 | B32: CAPSL-PR | C32: 50mm / Supreme Logo | D32: MS CAP SEAL PRINTED 50 MM (SUPREME LOGO) | E32: NOS | F32: 83099030
A33: CAPSL-PR-V52 | B33: CAPSL-PR | C33: 50mm / Viswaat Logo | D33: MS CAP SEAL PRINTED 50 MM (VISWAAT LOGO) | E33: NOS | F33: 83099030
A34: CAPSL-PR-V53 | B34: CAPSL-PR | C34: 50mm / Hsc Logo | D34: MS CAP SEAL PRINTED 50 MM (HSC LOGO) | E34: NOS | F34: 83099030
A35: CAPSL-PR-V54 | B35: CAPSL-PR | C35: 50mm / Unitop Logo | D35: MS CAP SEAL PRINTED 50 MM (UNITOP LOGO) | E35: NOS | F35: 83099030
A36: CAPSL-PR-V55 | B36: CAPSL-PR | C36: 50mm / Apl Logo | D36: MS CAP SEAL PRINTED 50 MM (APL LOGO) | E36: NOS | F36: 83099030
A37: CAPSL-PR-V56 | B37: CAPSL-PR | C37: 50mm / Indofil Industries Ltd | D37: MS CAP SEAL PRINTED 50 MM (INDOFIL INDUSTRIES LTD) | E37: NOS | F37: 83099030
A38: CAPSL-PR-V57 | B38: CAPSL-PR | C38: 50mm / Vr Petrochem Llp | D38: MS CAP SEAL PRINTED 50 MM (VR PETROCHEM LLP) | E38: NOS | F38: 83099030
A39: CAPSL-PR-V59 | B39: CAPSL-PR | C39: 50mm / Deepak Logo | D39: MS CAP SEAL PRINTED 50 MM (DEEPAK LOGO) | E39: NOS
A40: CAPSL-PR-V60 | B40: CAPSL-PR | C40: 50mm / Gacl Logo | D40: MS CAP SEAL PRINTED 50 MM (GACL LOGO) | E40: NOS | F40: 83099030
...

Sheet View_Combined (lookup)
A1: SKU Code | B1: Group SKU Code | C1: Group SKU Name | D1: Product Type | E1: Category | F1: Business Vertical | G1: Industry Standard Term | H1: Capacity/Size Value | I1: Unit | J1: Variant | K1: Original Item Name | L1: UOM | M1: HSN Code
A2: =T3_SKU!A2 -> BUNG-ORG | B2: =T3_SKU!B2 -> BUNG | C2: {=IFERROR(INDEX(T2_GroupSKU!$B:$B,MATCH(B2,T2_GroupSKU!$A:$A,0)),"")} -> Bung | D2: {=IFERROR(INDEX(T1_ProductType!$B:$B,MATCH(INDEX(T2_GroupSKU!$C:$C,MATCH(B2,T2_GroupSKU!$A:$A,0)),T1_ProductType!$A:$A,0)),"")} -> Bung | E2: {=IFERROR(INDEX(T1_ProductType!$C:$C,MATCH(INDEX(T2_GroupSKU!$C:$C,MATCH(B2,T2_GroupSKU!$A:$A,0)),T1_ProductType!$A:$A,0)),"")} -> Accessory | F2: {=IFERROR(INDEX(T1_ProductType!$D:$D,MATCH(INDEX(T2_GroupSKU!$C:$C,MATCH(B2,T2_GroupSKU!$A:$A,0)),T1_ProductType!$A:$A,0)),"")} -> Plastic Barrels | G2: {=IFERROR(IF(INDEX(T1_ProductType!$E:$E,MATCH(INDEX(T2_GroupSKU!$C:$C,MATCH(B2,T2_GroupSKU!$A:$A,0)),T1_ProductType!$A:$A,0))="","-",INDEX(T1_ProductType!$E:$E,MATCH(INDEX(T2_GroupSKU!$C:$C,MATCH(B2,T2_GroupSKU!$A:$A,0)),T1_ProductType!$A:$A,0))),"-")} -> - | H2: {=IFERROR(IF(INDEX(T2_GroupSKU!$D:$D,MATCH(B2,T2_GroupSKU!$A:$A,0))="","-",INDEX(T2_GroupSKU!$D:$D,MATCH(B2,T2_GroupSKU!$A:$A,0))),"-")} -> - | I2: {=IFERROR(IF(INDEX(T2_GroupSKU!$E:$E,MATCH(B2,T2_GroupSKU!$A:$A,0))="","-",INDEX(T2_GroupSKU!$E:$E,MATCH(B2,T2_GroupSKU!$A:$A,0))),"-")} -> - | J2: =T3_SKU!C2 -> Orange | K2: =T3_SKU!D2 -> BUNGS RING ORANGE | L2: =T3_SKU!E2 -> NOS | M2: =T3_SKU!F2
A3: =T3_SKU!A3 -> BUNG-V359 | B3: =T3_SKU!B3 -> BUNG | C3: {=IFERROR(INDEX(T2_GroupSKU!$B:$B,MATCH(B3,T2_GroupSKU!$A:$A,0)),"")} -> Bung | D3: {=IFERROR(INDEX(T1_ProductType!$B:$B,MATCH(INDEX(T2_GroupSKU!$C:$C,MATCH(B3,T2_GroupSKU!$A:$A,0)),T1_ProductType!$A:$A,0)),"")} -> Bung | E3: {=IFERROR(INDEX(T1_ProductType!$C:$C,MATCH(INDEX(T2_GroupSKU!$C:$C,MATCH(B3,T2_GroupSKU!$A:$A,0)),T1_ProductType!$A:$A,0)),"")} -> Accessory | F3: {=IFERROR(INDEX(T1_ProductType!$D:$D,MATCH(INDEX(T2_GroupSKU!$C:$C,MATCH(B3,T2_GroupSKU!$A:$A,0)),T1_ProductType!$A:$A,0)),"")} -> Plastic Barrels | G3: {=IFERROR(IF(INDEX(T1_ProductType!$E:$E,MATCH(INDEX(T2_GroupSKU!$C:$C,MATCH(B3,T2_GroupSKU!$A:$A,0)),T1_ProductType!$A:$A,0))="","-",INDEX(T1_ProductType!$E:$E,MATCH(INDEX(T2_GroupSKU!$C:$C,MATCH(B3,T2_GroupSKU!$A:$A,0)),T1_ProductType!$A:$A,0))),"-")} -> - | H3: {=IFERROR(IF(INDEX(T2_GroupSKU!$D:$D,MATCH(B3,T2_GroupSKU!$A:$A,0))="","-",INDEX(T2_GroupSKU!$D:$D,MATCH(B3,T2_GroupSKU!$A:$A,0))),"-")} -> - | I3: {=IFERROR(IF(INDEX(T2_GroupSKU!$E:$E,MATCH(B3,T2_GroupSKU!$A:$A,0))="","-",INDEX(T2_GroupSKU!$E:$E,MATCH(B3,T2_GroupSKU!$A:$A,0))),"-")} -> - | J3: =T3_SKU!C3 -> BUNGS RING | K3: =T3_SKU!D3 -> BUNGS RING | L3: =T3_SKU!E3 -> NOS | M3: =T3_SKU!F3 -> 39235010
A4: =T3_SKU!A4 -> BUNG-V408 | B4: =T3_SKU!B4 -> BUNG | C4: {=IFERROR(INDEX(T2_GroupSKU!$B:$B,MATCH(B4,T2_GroupSKU!$A:$A,0)),"")} -> Bung | D4: {=IFERROR(INDEX(T1_ProductType!$B:$B,MATCH(INDEX(T2_GroupSKU!$C:$C,MATCH(B4,T2_GroupSKU!$A:$A,0)),T1_ProductType!$A:$A,0)),"")} -> Bung | E4: {=IFERROR(INDEX(T1_ProductType!$C:$C,MATCH(INDEX(T2_GroupSKU!$C:$C,MATCH(B4,T2_GroupSKU!$A:$A,0)),T1_ProductType!$A:$A,0)),"")} -> Accessory | F4: {=IFERROR(INDEX(T1_ProductType!$D:$D,MATCH(INDEX(T2_GroupSKU!$C:$C,MATCH(B4,T2_GroupSKU!$A:$A,0)),T1_ProductType!$A:$A,0)),"")} -> Plastic Barrels | G4: {=IFERROR(IF(INDEX(T1_ProductType!$E:$E,MATCH(INDEX(T2_GroupSKU!$C:$C,MATCH(B4,T2_GroupSKU!$A:$A,0)),T1_ProductType!$A:$A,0))="","-",INDEX(T1_ProductType!$E:$E,MATCH(INDEX(T2_GroupSKU!$C:$C,MATCH(B4,T2_GroupSKU!$A:$A,0)),T1_ProductType!$A:$A,0))),"-")} -> - | H4: {=IFERROR(IF(INDEX(T2_GroupSKU!$D:$D,MATCH(B4,T2_GroupSKU!$A:$A,0))="","-",INDEX(T2_GroupSKU!$D:$D,MATCH(B4,T2_GroupSKU!$A:$A,0))),"-")} -> - | I4: {=IFERROR(IF(INDEX(T2_GroupSKU!$E:$E,MATCH(B4,T2_GroupSKU!$A:$A,0))="","-",INDEX(T2_GroupSKU!$E:$E,MATCH(B4,T2_GroupSKU!$A:$A,0))),"-")} -> - | J4: =T3_SKU!C4 -> BUNGS | K4: =T3_SKU!D4 -> BUNGS | L4: =T3_SKU!E4 -> nos | M4: =T3_SKU!F4 -> 39235010
A5: =T3_SKU!A5 -> BUNG-V409 | B5: =T3_SKU!B5 -> BUNG | C5: {=IFERROR(INDEX(T2_GroupSKU!$B:$B,MATCH(B5,T2_GroupSKU!$A:$A,0)),"")} -> Bung | D5: {=IFERROR(INDEX(T1_ProductType!$B:$B,MATCH(INDEX(T2_GroupSKU!$C:$C,MATCH(B5,T2_GroupSKU!$A:$A,0)),T1_ProductType!$A:$A,0)),"")} -> Bung | E5: {=IFERROR(INDEX(T1_ProductType!$C:$C,MATCH(INDEX(T2_GroupSKU!$C:$C,MATCH(B5,T2_GroupSKU!$A:$A,0)),T1_ProductType!$A:$A,0)),"")} -> Accessory | F5: {=IFERROR(INDEX(T1_ProductType!$D:$D,MATCH(INDEX(T2_GroupSKU!$C:$C,MATCH(B5,T2_GroupSKU!$A:$A,0)),T1_ProductType!$A:$A,0)),"")} -> Plastic Barrels | G5: {=IFERROR(IF(INDEX(T1_ProductType!$E:$E,MATCH(INDEX(T2_GroupSKU!$C:$C,MATCH(B5,T2_GroupSKU!$A:$A,0)),T1_ProductType!$A:$A,0))="","-",INDEX(T1_ProductType!$E:$E,MATCH(INDEX(T2_GroupSKU!$C:$C,MATCH(B5,T2_GroupSKU!$A:$A,0)),T1_ProductType!$A:$A,0))),"-")} -> - | H5: {=IFERROR(IF(INDEX(T2_GroupSKU!$D:$D,MATCH(B5,T2_GroupSKU!$A:$A,0))="","-",INDEX(T2_GroupSKU!$D:$D,MATCH(B5,T2_GroupSKU!$A:$A,0))),"-")} -> - | I5: {=IFERROR(IF(INDEX(T2_GroupSKU!$E:$E,MATCH(B5,T2_GroupSKU!$A:$A,0))="","-",INDEX(T2_GroupSKU!$E:$E,MATCH(B5,T2_GroupSKU!$A:$A,0))),"-")} -> - | J5: =T3_SKU!C5 -> 70mm / Ibc | K5: =T3_SKU!D5 -> BUNGS 70 MM ( IBC ) | L5: =T3_SKU!E5 -> NOS | M5: =T3_SKU!F5 -> 39235010
A6: =T3_SKU!A6 -> BUNG-V41 | B6: =T3_SKU!B6 -> BUNG | C6: {=IFERROR(INDEX(T2_GroupSKU!$B:$B,MATCH(B6,T2_GroupSKU!$A:$A,0)),"")} -> Bung | D6: {=IFERROR(INDEX(T1_ProductType!$B:$B,MATCH(INDEX(T2_GroupSKU!$C:$C,MATCH(B6,T2_GroupSKU!$A:$A,0)),T1_ProductType!$A:$A,0)),"")} -> Bung | E6: {=IFERROR(INDEX(T1_ProductType!$C:$C,MATCH(INDEX(T2_GroupSKU!$C:$C,MATCH(B6,T2_GroupSKU!$A:$A,0)),T1_ProductType!$A:$A,0)),"")} -> Accessory | F6: {=IFERROR(INDEX(T1_ProductType!$D:$D,MATCH(INDEX(T2_GroupSKU!$C:$C,MATCH(B6,T2_GroupSKU!$A:$A,0)),T1_ProductType!$A:$A,0)),"")} -> Plastic Barrels | G6: {=IFERROR(IF(INDEX(T1_ProductType!$E:$E,MATCH(INDEX(T2_GroupSKU!$C:$C,MATCH(B6,T2_GroupSKU!$A:$A,0)),T1_ProductType!$A:$A,0))="","-",INDEX(T1_ProductType!$E:$E,MATCH(INDEX(T2_GroupSKU!$C:$C,MATCH(B6,T2_GroupSKU!$A:$A,0)),T1_ProductType!$A:$A,0))),"-")} -> - | H6: {=IFERROR(IF(INDEX(T2_GroupSKU!$D:$D,MATCH(B6,T2_GroupSKU!$A:$A,0))="","-",INDEX(T2_GroupSKU!$D:$D,MATCH(B6,T2_GroupSKU!$A:$A,0))),"-")} -> - | I6: {=IFERROR(IF(INDEX(T2_GroupSKU!$E:$E,MATCH(B6,T2_GroupSKU!$A:$A,0))="","-",INDEX(T2_GroupSKU!$E:$E,MATCH(B6,T2_GroupSKU!$A:$A,0))),"-")} -> - | J6: =T3_SKU!C6 -> BUNGS DG | K6: =T3_SKU!D6 -> BUNGS DG | L6: =T3_SKU!E6 -> NOS | M6: =T3_SKU!F6 -> 39235010
A7: =T3_SKU!A7 -> BUNG-V442 | B7: =T3_SKU!B7 -> BUNG | C7: {=IFERROR(INDEX(T2_GroupSKU!$B:$B,MATCH(B7,T2_GroupSKU!$A:$A,0)),"")} -> Bung | D7: {=IFERROR(INDEX(T1_ProductType!$B:$B,MATCH(INDEX(T2_GroupSKU!$C:$C,MATCH(B7,T2_GroupSKU!$A:$A,0)),T1_ProductType!$A:$A,0)),"")} -> Bung | E7: {=IFERROR(INDEX(T1_ProductType!$C:$C,MATCH(INDEX(T2_GroupSKU!$C:$C,MATCH(B7,T2_GroupSKU!$A:$A,0)),T1_ProductType!$A:$A,0)),"")} -> Accessory | F7: {=IFERROR(INDEX(T1_ProductType!$D:$D,MATCH(INDEX(T2_GroupSKU!$C:$C,MATCH(B7,T2_GroupSKU!$A:$A,0)),T1_ProductType!$A:$A,0)),"")} -> Plastic Barrels | G7: {=IFERROR(IF(INDEX(T1_ProductType!$E:$E,MATCH(INDEX(T2_GroupSKU!$C:$C,MATCH(B7,T2_GroupSKU!$A:$A,0)),T1_ProductType!$A:$A,0))="","-",INDEX(T1_ProductType!$E:$E,MATCH(INDEX(T2_GroupSKU!$C:$C,MATCH(B7,T2_GroupSKU!$A:$A,0)),T1_ProductType!$A:$A,0))),"-")} -> - | H7: {=IFERROR(IF(INDEX(T2_GroupSKU!$D:$D,MATCH(B7,T2_GroupSKU!$A:$A,0))="","-",INDEX(T2_GroupSKU!$D:$D,MATCH(B7,T2_GroupSKU!$A:$A,0))),"-")} -> - | I7: {=IFERROR(IF(INDEX(T2_GroupSKU!$E:$E,MATCH(B7,T2_GroupSKU!$A:$A,0))="","-",INDEX(T2_GroupSKU!$E:$E,MATCH(B7,T2_GroupSKU!$A:$A,0))),"-")} -> - | J7: =T3_SKU!C7 -> 50mm / Ibc | K7: =T3_SKU!D7 -> BUNGS 50 MM ( IBC ) | L7: =T3_SKU!E7 -> NOS | M7: =T3_SKU!F7 -> 39235010
A8: =T3_SKU!A8 -> BUNG-V444 | B8: =T3_SKU!B8 -> BUNG | C8: {=IFERROR(INDEX(T2_GroupSKU!$B:$B,MATCH(B8,T2_GroupSKU!$A:$A,0)),"")} -> Bung | D8: {=IFERROR(INDEX(T1_ProductType!$B:$B,MATCH(INDEX(T2_GroupSKU!$C:$C,MATCH(B8,T2_GroupSKU!$A:$A,0)),T1_ProductType!$A:$A,0)),"")} -> Bung | E8: {=IFERROR(INDEX(T1_ProductType!$C:$C,MATCH(INDEX(T2_GroupSKU!$C:$C,MATCH(B8,T2_GroupSKU!$A:$A,0)),T1_ProductType!$A:$A,0)),"")} -> Accessory | F8: {=IFERROR(INDEX(T1_ProductType!$D:$D,MATCH(INDEX(T2_GroupSKU!$C:$C,MATCH(B8,T2_GroupSKU!$A:$A,0)),T1_ProductType!$A:$A,0)),"")} -> Plastic Barrels | G8: {=IFERROR(IF(INDEX(T1_ProductType!$E:$E,MATCH(INDEX(T2_GroupSKU!$C:$C,MATCH(B8,T2_GroupSKU!$A:$A,0)),T1_ProductType!$A:$A,0))="","-",INDEX(T1_ProductType!$E:$E,MATCH(INDEX(T2_GroupSKU!$C:$C,MATCH(B8,T2_GroupSKU!$A:$A,0)),T1_ProductType!$A:$A,0))),"-")} -> - | H8: {=IFERROR(IF(INDEX(T2_GroupSKU!$D:$D,MATCH(B8,T2_GroupSKU!$A:$A,0))="","-",INDEX(T2_GroupSKU!$D:$D,MATCH(B8,T2_GroupSKU!$A:$A,0))),"-")} -> - | I8: {=IFERROR(IF(INDEX(T2_GroupSKU!$E:$E,MATCH(B8,T2_GroupSKU!$A:$A,0))="","-",INDEX(T2_GroupSKU!$E:$E,MATCH(B8,T2_GroupSKU!$A:$A,0))),"-")} -> - | J8: =T3_SKU!C8 -> 50mm / Galaxy | K8: =T3_SKU!D8 -> BUNGS 50 MM (GALAXY) | L8: =T3_SKU!E8 | M8: =T3_SKU!F8
A9: =T3_SKU!A9 -> BUNG-V445 | B9: =T3_SKU!B9 -> BUNG | C9: {=IFERROR(INDEX(T2_GroupSKU!$B:$B,MATCH(B9,T2_GroupSKU!$A:$A,0)),"")} -> Bung | D9: {=IFERROR(INDEX(T1_ProductType!$B:$B,MATCH(INDEX(T2_GroupSKU!$C:$C,MATCH(B9,T2_GroupSKU!$A:$A,0)),T1_ProductType!$A:$A,0)),"")} -> Bung | E9: {=IFERROR(INDEX(T1_ProductType!$C:$C,MATCH(INDEX(T2_GroupSKU!$C:$C,MATCH(B9,T2_GroupSKU!$A:$A,0)),T1_ProductType!$A:$A,0)),"")} -> Accessory | F9: {=IFERROR(INDEX(T1_ProductType!$D:$D,MATCH(INDEX(T2_GroupSKU!$C:$C,MATCH(B9,T2_GroupSKU!$A:$A,0)),T1_ProductType!$A:$A,0)),"")} -> Plastic Barrels | G9: {=IFERROR(IF(INDEX(T1_ProductType!$E:$E,MATCH(INDEX(T2_GroupSKU!$C:$C,MATCH(B9,T2_GroupSKU!$A:$A,0)),T1_ProductType!$A:$A,0))="","-",INDEX(T1_ProductType!$E:$E,MATCH(INDEX(T2_GroupSKU!$C:$C,MATCH(B9,T2_GroupSKU!$A:$A,0)),T1_ProductType!$A:$A,0))),"-")} -> - | H9: {=IFERROR(IF(INDEX(T2_GroupSKU!$D:$D,MATCH(B9,T2_GroupSKU!$A:$A,0))="","-",INDEX(T2_GroupSKU!$D:$D,MATCH(B9,T2_GroupSKU!$A:$A,0))),"-")} -> - | I9: {=IFERROR(IF(INDEX(T2_GroupSKU!$E:$E,MATCH(B9,T2_GroupSKU!$A:$A,0))="","-",INDEX(T2_GroupSKU!$E:$E,MATCH(B9,T2_GroupSKU!$A:$A,0))),"-")} -> - | J9: =T3_SKU!C9 -> BUNGS SOFT RING | K9: =T3_SKU!D9 -> BUNGS SOFT RING | L9: =T3_SKU!E9 | M9: =T3_SKU!F9
A10: =T3_SKU!A10 -> BUNG-V447 | B10: =T3_SKU!B10 -> BUNG | C10: {=IFERROR(INDEX(T2_GroupSKU!$B:$B,MATCH(B10,T2_GroupSKU!$A:$A,0)),"")} -> Bung | D10: {=IFERROR(INDEX(T1_ProductType!$B:$B,MATCH(INDEX(T2_GroupSKU!$C:$C,MATCH(B10,T2_GroupSKU!$A:$A,0)),T1_ProductType!$A:$A,0)),"")} -> Bung | E10: {=IFERROR(INDEX(T1_ProductType!$C:$C,MATCH(INDEX(T2_GroupSKU!$C:$C,MATCH(B10,T2_GroupSKU!$A:$A,0)),T1_ProductType!$A:$A,0)),"")} -> Accessory | F10: {=IFERROR(INDEX(T1_ProductType!$D:$D,MATCH(INDEX(T2_GroupSKU!$C:$C,MATCH(B10,T2_GroupSKU!$A:$A,0)),T1_ProductType!$A:$A,0)),"")} -> Plastic Barrels | G10: {=IFERROR(IF(INDEX(T1_ProductType!$E:$E,MATCH(INDEX(T2_GroupSKU!$C:$C,MATCH(B10,T2_GroupSKU!$A:$A,0)),T1_ProductType!$A:$A,0))="","-",INDEX(T1_ProductType!$E:$E,MATCH(INDEX(T2_GroupSKU!$C:$C,MATCH(B10,T2_GroupSKU!$A:$A,0)),T1_ProductType!$A:$A,0))),"-")} -> - | H10: {=IFERROR(IF(INDEX(T2_GroupSKU!$D:$D,MATCH(B10,T2_GroupSKU!$A:$A,0))="","-",INDEX(T2_GroupSKU!$D:$D,MATCH(B10,T2_GroupSKU!$A:$A,0))),"-")} -> - | I10: {=IFERROR(IF(INDEX(T2_GroupSKU!$E:$E,MATCH(B10,T2_GroupSKU!$A:$A,0))="","-",INDEX(T2_GroupSKU!$E:$E,MATCH(B10,T2_GroupSKU!$A:$A,0))),"-")} -> - | J10: =T3_SKU!C10 -> 65mm | K10: =T3_SKU!D10 -> TOP SEAL BUNGS 65 MM | L10: =T3_SKU!E10 | M10: =T3_SKU!F10
A11: =T3_SKU!A11 -> CAPSL-PR-BLK | B11: =T3_SKU!B11 -> CAPSL-PR | C11: {=IFERROR(INDEX(T2_GroupSKU!$B:$B,MATCH(B11,T2_GroupSKU!$A:$A,0)),"")} -> Printed Cap Seal (Branded) | D11: {=IFERROR(INDEX(T1_ProductType!$B:$B,MATCH(INDEX(T2_GroupSKU!$C:$C,MATCH(B11,T2_GroupSKU!$A:$A,0)),T1_ProductType!$A:$A,0)),"")} -> Printed Cap Seal (Branded) | E11: {=IFERROR(INDEX(T1_ProductType!$C:$C,MATCH(INDEX(T2_GroupSKU!$C:$C,MATCH(B11,T2_GroupSKU!$A:$A,0)),T1_ProductType!$A:$A,0)),"")} -> Accessory | F11: {=IFERROR(INDEX(T1_ProductType!$D:$D,MATCH(INDEX(T2_GroupSKU!$C:$C,MATCH(B11,T2_GroupSKU!$A:$A,0)),T1_ProductType!$A:$A,0)),"")} -> Plastic Barrels | G11: {=IFERROR(IF(INDEX(T1_ProductType!$E:$E,MATCH(INDEX(T2_GroupSKU!$C:$C,MATCH(B11,T2_GroupSKU!$A:$A,0)),T1_ProductType!$A:$A,0))="","-",INDEX(T1_ProductType!$E:$E,MATCH(INDEX(T2_GroupSKU!$C:$C,MATCH(B11,T2_GroupSKU!$A:$A,0)),T1_ProductType!$A:$A,0))),"-")} -> - | H11: {=IFERROR(IF(INDEX(T2_GroupSKU!$D:$D,MATCH(B11,T2_GroupSKU!$A:$A,0))="","-",INDEX(T2_GroupSKU!$D:$D,MATCH(B11,T2_GroupSKU!$A:$A,0))),"-")} -> - | I11: {=IFERROR(IF(INDEX(T2_GroupSKU!$E:$E,MATCH(B11,T2_GroupSKU!$A:$A,0))="","-",INDEX(T2_GroupSKU!$E:$E,MATCH(B11,T2_GroupSKU!$A:$A,0))),"-")} -> - | J11: =T3_SKU!C11 -> 50mm / Black / Black Rose | K11: =T3_SKU!D11 -> MS CAP SEAL PRINTED 50 MM (BLACK ROSE) | L11: =T3_SKU!E11 -> NOS | M11: =T3_SKU!F11 -> 83099030
A12: =T3_SKU!A12 -> CAPSL-PR-V22 | B12: =T3_SKU!B12 -> CAPSL-PR | C12: {=IFERROR(INDEX(T2_GroupSKU!$B:$B,MATCH(B12,T2_GroupSKU!$A:$A,0)),"")} -> Printed Cap Seal (Branded) | D12: {=IFERROR(INDEX(T1_ProductType!$B:$B,MATCH(INDEX(T2_GroupSKU!$C:$C,MATCH(B12,T2_GroupSKU!$A:$A,0)),T1_ProductType!$A:$A,0)),"")} -> Printed Cap Seal (Branded) | E12: {=IFERROR(INDEX(T1_ProductType!$C:$C,MATCH(INDEX(T2_GroupSKU!$C:$C,MATCH(B12,T2_GroupSKU!$A:$A,0)),T1_ProductType!$A:$A,0)),"")} -> Accessory | F12: {=IFERROR(INDEX(T1_ProductType!$D:$D,MATCH(INDEX(T2_GroupSKU!$C:$C,MATCH(B12,T2_GroupSKU!$A:$A,0)),T1_ProductType!$A:$A,0)),"")} -> Plastic Barrels | G12: {=IFERROR(IF(INDEX(T1_ProductType!$E:$E,MATCH(INDEX(T2_GroupSKU!$C:$C,MATCH(B12,T2_GroupSKU!$A:$A,0)),T1_ProductType!$A:$A,0))="","-",INDEX(T1_ProductType!$E:$E,MATCH(INDEX(T2_GroupSKU!$C:$C,MATCH(B12,T2_GroupSKU!$A:$A,0)),T1_ProductType!$A:$A,0))),"-")} -> - | H12: {=IFERROR(IF(INDEX(T2_GroupSKU!$D:$D,MATCH(B12,T2_GroupSKU!$A:$A,0))="","-",INDEX(T2_GroupSKU!$D:$D,MATCH(B12,T2_GroupSKU!$A:$A,0))),"-")} -> - | I12: {=IFERROR(IF(INDEX(T2_GroupSKU!$E:$E,MATCH(B12,T2_GroupSKU!$A:$A,0))="","-",INDEX(T2_GroupSKU!$E:$E,MATCH(B12,T2_GroupSKU!$A:$A,0))),"-")} -> - | J12: =T3_SKU!C12 -> 50mm / Aditya Birla Logo | K12: =T3_SKU!D12 -> MS CAP SEAL PRINTED 50 MM (ADITYA BIRLA LOGO) | L12: =T3_SKU!E12 -> NOS | M12: =T3_SKU!F12 -> 83099090
A13: =T3_SKU!A13 -> CAPSL-PR-V23 | B13: =T3_SKU!B13 -> CAPSL-PR | C13: {=IFERROR(INDEX(T2_GroupSKU!$B:$B,MATCH(B13,T2_GroupSKU!$A:$A,0)),"")} -> Printed Cap Seal (Branded) | D13: {=IFERROR(INDEX(T1_ProductType!$B:$B,MATCH(INDEX(T2_GroupSKU!$C:$C,MATCH(B13,T2_GroupSKU!$A:$A,0)),T1_ProductType!$A:$A,0)),"")} -> Printed Cap Seal (Branded) | E13: {=IFERROR(INDEX(T1_ProductType!$C:$C,MATCH(INDEX(T2_GroupSKU!$C:$C,MATCH(B13,T2_GroupSKU!$A:$A,0)),T1_ProductType!$A:$A,0)),"")} -> Accessory | F13: {=IFERROR(INDEX(T1_ProductType!$D:$D,MATCH(INDEX(T2_GroupSKU!$C:$C,MATCH(B13,T2_GroupSKU!$A:$A,0)),T1_ProductType!$A:$A,0)),"")} -> Plastic Barrels | G13: {=IFERROR(IF(INDEX(T1_ProductType!$E:$E,MATCH(INDEX(T2_GroupSKU!$C:$C,MATCH(B13,T2_GroupSKU!$A:$A,0)),T1_ProductType!$A:$A,0))="","-",INDEX(T1_ProductType!$E:$E,MATCH(INDEX(T2_GroupSKU!$C:$C,MATCH(B13,T2_GroupSKU!$A:$A,0)),T1_ProductType!$A:$A,0))),"-")} -> - | H13: {=IFERROR(IF(INDEX(T2_GroupSKU!$D:$D,MATCH(B13,T2_GroupSKU!$A:$A,0))="","-",INDEX(T2_GroupSKU!$D:$D,MATCH(B13,T2_GroupSKU!$A:$A,0))),"-")} -> - | I13: {=IFERROR(IF(INDEX(T2_GroupSKU!$E:$E,MATCH(B13,T2_GroupSKU!$A:$A,0))="","-",INDEX(T2_GroupSKU!$E:$E,MATCH(B13,T2_GroupSKU!$A:$A,0))),"-")} -> - | J13: =T3_SKU!C13 -> 75mm / Charbhuja Logo | K13: =T3_SKU!D13 -> MS CAP SEAL PRINTED 75 MM (CHARBHUJA LOGO) | L13: =T3_SKU!E13 -> NOS | M13: =T3_SKU!F13 -> 83099030
... A449: =T3_SKU!A449 -> WMD-50-YEL-28KG | B449: =T3_SKU!B449 -> WMD-50 | C449: {=IFERROR(INDEX(T2_GroupSKU!$B:$B,MATCH(B449,T2_GroupSKU!$A:$A,0)),"")} -> Wide Mouth Drum - 50.0 LTR | D449: {=IFERROR(INDEX(T1_ProductType!$B:$B,MATCH(INDEX(T2_GroupSKU!$C:$C,MATCH(B449,T2_GroupSKU!$A:$A,0)),T1_ProductType!$A:$A,0)),"")} -> Wide Mouth Drum | E449: {=IFERROR(INDEX(T1_ProductType!$C:$C,MATCH(INDEX(T2_GroupSKU!$C:$C,MATCH(B449,T2_GroupSKU!$A:$A,0)),T1_ProductType!$A:$A,0)),"")} -> Drum | F449: {=IFERROR(INDEX(T1_ProductType!$D:$D,MATCH(INDEX(T2_GroupSKU!$C:$C,MATCH(B449,T2_GroupSKU!$A:$A,0)),T1_ProductType!$A:$A,0)),"")} -> Plastic Barrels | G449: {=IFERROR(IF(INDEX(T1_ProductType!$E:$E,MATCH(INDEX(T2_GroupSKU!$C:$C,MATCH(B449,T2_GroupSKU!$A:$A,0)),T1_ProductType!$A:$A,0))="","-",INDEX(T1_ProductType!$E:$E,MATCH(INDEX(T2_GroupSKU!$C:$C,MATCH(B449,T2_GroupSKU!$A:$A,0)),T1_ProductType!$A:$A,0))),"-")} -> Open Head Drum | H449: {=IFERROR(IF(INDEX(T2_GroupSKU!$D:$D,MATCH(B449,T2_GroupSKU!$A:$A,0))="","-",INDEX(T2_GroupSKU!$D:$D,MATCH(B449,T2_GroupSKU!$A:$A,0))),"-")} -> 50 | I449: {=IFERROR(IF(INDEX(T2_GroupSKU!$E:$E,MATCH(B449,T2_GroupSKU!$A:$A,0))="","-",INDEX(T2_GroupSKU!$E:$E,MATCH(B449,T2_GroupSKU!$A:$A,0))),"-")} -> LTR | J449: =T3_SKU!C449 -> Yellow / 2.8 KG | K449: =T3_SKU!D449 -> 50 LTR YELLOW W/M 2.8 KG | L449: =T3_SKU!E449 -> NOS | M449: =T3_SKU!F449 -> 39233090
